
AttributeError
AttributeError: 'OtherTransaction' object has no attribute 'user'

Traceback (most recent call last)
File "/home/runner/workspace/.pythonlibs/lib/python3.11/site-packages/flask/app.py", line 1536, in __call__
return self.wsgi_app(environ, start_response)
       ^^^^^^^^^^^^^^^^^^^^^^^^^^^^^^^^^^^^^^
File "/home/runner/workspace/.pythonlibs/lib/python3.11/site-packages/flask_socketio/__init__.py", line 42, in __call__
return super().__call__(environ, start_response)
       ^^^^^^^^^^^^^^^^^^^^^^^^^^^^^^^^^^^^^^^^^
File "/home/runner/workspace/.pythonlibs/lib/python3.11/site-packages/engineio/middleware.py", line 74, in __call__
return self.wsgi_app(environ, start_response)
       ^^^^^^^^^^^^^^^^^^^^^^^^^^^^^^^^^^^^^^
File "/home/runner/workspace/.pythonlibs/lib/python3.11/site-packages/flask/app.py", line 1514, in wsgi_app
response = self.handle_exception(e)
           ^^^^^^^^^^^^^^^^^^^^^^^^
File "/home/runner/workspace/.pythonlibs/lib/python3.11/site-packages/flask/app.py", line 1511, in wsgi_app
response = self.full_dispatch_request()
           ^^^^^^^^^^^^^^^^^^^^^^^^^^^^
File "/home/runner/workspace/.pythonlibs/lib/python3.11/site-packages/flask/app.py", line 919, in full_dispatch_request
rv = self.handle_user_exception(e)
     ^^^^^^^^^^^^^^^^^^^^^^^^^^^^^
File "/home/runner/workspace/.pythonlibs/lib/python3.11/site-packages/flask/app.py", line 917, in full_dispatch_request
rv = self.dispatch_request()
     ^^^^^^^^^^^^^^^^^^^^^^^
File "/home/runner/workspace/.pythonlibs/lib/python3.11/site-packages/flask/app.py", line 902, in dispatch_request
return self.ensure_sync(self.view_functions[rule.endpoint])(**view_args)  # type: ignore[no-any-return]
       ^^^^^^^^^^^^^^^^^^^^^^^^^^^^^^^^^^^^^^^^^^^^^^^^^^^^^^^^^^^^^^^^^
File "/home/runner/workspace/.pythonlibs/lib/python3.11/site-packages/flask_login/utils.py", line 290, in decorated_view
return current_app.ensure_sync(func)(*args, **kwargs)
       ^^^^^^^^^^^^^^^^^^^^^^^^^^^^^^^^^^^^^^^^^^^^^^
File "/home/runner/workspace/routes/other_transactions.py", line 49, in index
'username': transaction.user.username if transaction.user else "غير معروف"
                                         ^^^^^^^^^^^^^^^^
AttributeError: 'OtherTransaction' object has no attribute 'user'
The debugger caught an exception in your WSGI application. You can now look at the traceback which led to the error.
To switch between the interactive traceback and the plaintext one, you can click on the "Traceback" headline. From the text traceback you can also create a paste of it.

Brought to you by DON'T PANIC, your friendly Werkzeug powered traceback interpreter.